<?xml version="1.0"?>
<sdf version="1.10">
  <world name="tm_turtlebot_world">
    <plugin filename="gz-sim-physics-system" name="gz::sim::systems::Physics"/>
    <plugin filename="gz-sim-user-commands-system" name="gz::sim::systems::UserCommands"/>
    <plugin filename="gz-sim-scene-broadcaster-system" name="gz::sim::systems::SceneBroadcaster"/>
    <plugin filename="gz-sim-sensors-system" name="gz::sim::systems::Sensors">
      <render_engine>ogre2</render_engine>
    </plugin>

    <gravity>0 0 -9.8</gravity>
    <magnetic_field>6e-06 2.3e-05 -4.2e-05</magnetic_field>
    <atmosphere type="adiabatic"/>

    <light name="sun" type="directional">
      <cast_shadows>true</cast_shadows>
      <pose>0 0 10 0 0 0</pose>
      <diffuse>0.8 0.8 0.8 1</diffuse>
      <specular>0.2 0.2 0.2 1</specular>
      <attenuation>
        <range>1000</range>
        <constant>0.9</constant>
        <linear>0.01</linear>
        <quadratic>0.001</quadratic>
      </attenuation>
      <direction>-0.5 0.1 -0.9</direction>
    </light>

    <model name="ground_plane">
      <static>true</static>
      <link name="link">
        <collision name="collision">
          <geometry>
            <plane>
              <normal>0 0 1</normal>
              <size>20 20</size>
            </plane>
          </geometry>
        </collision>
        <visual name="visual">
          <geometry>
            <plane>
              <normal>0 0 1</normal>
              <size>20 20</size>
            </plane>
          </geometry>
          <material>
            <ambient>0.45 0.48 0.5 1</ambient>
            <diffuse>0.45 0.48 0.5 1</diffuse>
          </material>
        </visual>
      </link>
    </model>

    <model name="tm_turtlebot">
      <pose>0 0 0.08 0 0 0</pose>
      <link name="base_link">
        <inertial>
          <mass>2.0</mass>
          <inertia>
            <ixx>0.03</ixx>
            <iyy>0.03</iyy>
            <izz>0.05</izz>
          </inertia>
        </inertial>
        <collision name="base_collision">
          <geometry>
            <cylinder>
              <radius>0.18</radius>
              <length>0.12</length>
            </cylinder>
          </geometry>
        </collision>
        <visual name="base_visual">
          <geometry>
            <cylinder>
              <radius>0.18</radius>
              <length>0.12</length>
            </cylinder>
          </geometry>
          <material>
            <ambient>0.05 0.08 0.1 1</ambient>
            <diffuse>0.05 0.08 0.1 1</diffuse>
          </material>
        </visual>
        <sensor name="lidar" type="gpu_lidar">
          <pose>0 0 0.13 0 0 0</pose>
          <topic>/scan</topic>
          <update_rate>10</update_rate>
          <ray>
            <scan>
              <horizontal>
                <samples>180</samples>
                <resolution>1</resolution>
                <min_angle>-3.14159</min_angle>
                <max_angle>3.14159</max_angle>
              </horizontal>
            </scan>
            <range>
              <min>0.12</min>
              <max>8.0</max>
              <resolution>0.01</resolution>
            </range>
          </ray>
          <always_on>true</always_on>
          <visualize>true</visualize>
        </sensor>
      </link>

      <link name="left_wheel">
        <pose>0 0.16 -0.02 1.5708 0 0</pose>
        <inertial>
          <mass>0.2</mass>
          <inertia>
            <ixx>0.001</ixx>
            <iyy>0.001</iyy>
            <izz>0.001</izz>
          </inertia>
        </inertial>
        <collision name="collision">
          <geometry>
            <cylinder>
              <radius>0.055</radius>
              <length>0.035</length>
            </cylinder>
          </geometry>
        </collision>
        <visual name="visual">
          <geometry>
            <cylinder>
              <radius>0.055</radius>
              <length>0.035</length>
            </cylinder>
          </geometry>
          <material>
            <ambient>0.01 0.01 0.01 1</ambient>
            <diffuse>0.01 0.01 0.01 1</diffuse>
          </material>
        </visual>
      </link>

      <link name="right_wheel">
        <pose>0 -0.16 -0.02 1.5708 0 0</pose>
        <inertial>
          <mass>0.2</mass>
          <inertia>
            <ixx>0.001</ixx>
            <iyy>0.001</iyy>
            <izz>0.001</izz>
          </inertia>
        </inertial>
        <collision name="collision">
          <geometry>
            <cylinder>
              <radius>0.055</radius>
              <length>0.035</length>
            </cylinder>
          </geometry>
        </collision>
        <visual name="visual">
          <geometry>
            <cylinder>
              <radius>0.055</radius>
              <length>0.035</length>
            </cylinder>
          </geometry>
          <material>
            <ambient>0.01 0.01 0.01 1</ambient>
            <diffuse>0.01 0.01 0.01 1</diffuse>
          </material>
        </visual>
      </link>

      <link name="caster">
        <pose>-0.13 0 -0.045 0 0 0</pose>
        <collision name="collision">
          <geometry>
            <sphere>
              <radius>0.025</radius>
            </sphere>
          </geometry>
        </collision>
        <visual name="visual">
          <geometry>
            <sphere>
              <radius>0.025</radius>
            </sphere>
          </geometry>
          <material>
            <ambient>0.02 0.02 0.02 1</ambient>
            <diffuse>0.02 0.02 0.02 1</diffuse>
          </material>
        </visual>
      </link>

      <joint name="left_wheel_joint" type="revolute">
        <parent>base_link</parent>
        <child>left_wheel</child>
        <axis>
          <xyz>0 1 0</xyz>
          <limit>
            <lower>-1e16</lower>
            <upper>1e16</upper>
          </limit>
        </axis>
      </joint>

      <joint name="right_wheel_joint" type="revolute">
        <parent>base_link</parent>
        <child>right_wheel</child>
        <axis>
          <xyz>0 1 0</xyz>
          <limit>
            <lower>-1e16</lower>
            <upper>1e16</upper>
          </limit>
        </axis>
      </joint>

      <joint name="caster_joint" type="ball">
        <parent>base_link</parent>
        <child>caster</child>
      </joint>

      <plugin filename="gz-sim-diff-drive-system" name="gz::sim::systems::DiffDrive">
        <left_joint>left_wheel_joint</left_joint>
        <right_joint>right_wheel_joint</right_joint>
        <wheel_separation>0.32</wheel_separation>
        <wheel_radius>0.055</wheel_radius>
        <topic>/model/tm_turtlebot/cmd_vel</topic>
        <odom_topic>/model/tm_turtlebot/odometry</odom_topic>
        <frame_id>odom</frame_id>
        <child_frame_id>base_link</child_frame_id>
      </plugin>
    </model>

    <model name="box_obstacle">
      <static>true</static>
      <pose>1.5 0.8 0.25 0 0 0</pose>
      <link name="link">
        <collision name="collision">
          <geometry>
            <box>
              <size>0.5 0.5 0.5</size>
            </box>
          </geometry>
        </collision>
        <visual name="visual">
          <geometry>
            <box>
              <size>0.5 0.5 0.5</size>
            </box>
          </geometry>
          <material>
            <ambient>0.7 0.15 0.08 1</ambient>
            <diffuse>0.7 0.15 0.08 1</diffuse>
          </material>
        </visual>
      </link>
    </model>
  </world>
</sdf>
